Workbook

Sheet Ozet Dashboard
A1: OZET DASHBOARD | Kalan 14 Is Gunu
A2: Tum degerler 'Sprint Plani' sayfasindan formullerle hesaplanir. Bu sayfaya elle deger girmeyin.
A4: PROJE KUNYESI
A5: Proje | B5: Kalori Sayacı + Akıllı Öneri Asistanı (Android)
A6: Kalan süre | B6: 14 iş günü × 9 saat = 126 saat (Gün 7 → Gün 20)
A7: Alt bar | B7: Sohbet · Keşfet (swipe) · Kalori · Kiler
A8: Alışveriş listesi | B8: Sekme değil — Kiler sekmesi altında alt ekran
A9: Mobil | B9: Flutter + Dart + Material 3 + Riverpod + go_router + flutter_card_swiper
A10: Backend | B10: Python / FastAPI (hazır) + yeni AI uçları
A11: İlişkisel DB | B11: SQLite — 22 tablo (revize: pantry_items, recipe_feedback, +swipe_sessions, +vision_requests)
A12: Doküman DB | B12: MongoDB Atlas M0 — recipes koleksiyonu (100+ tarif)
A13: Görme modeli | B13: Çok kipli (multimodal) LLM — fotoğraftan malzeme ve öğün tanıma
A14: Sohbet | B14: Groq / LLaMA 3 + RAG (kiler + profil + filtrelenmiş tarifler)
A15: Barkod | B15: Google ML Kit (mobile_scanner) — cihaz üstü, ücretsiz
A16: Dış veri | B16: Open Food Facts (barkod + besin değeri)
... A19: Kapsam dışı | B19: Fiş OCR, özel obje tanıma modeli eğitimi, iOS sürümü, gıda israfı raporu
A21: HAFTALIK EFOR DAGILIMI
A22: Hafta | B22: Görev Sayısı | C22: Toplam Saat | D22: Tamamlanan Saat | E22: İlerleme % | F22: Odak
A23: Hafta 2 | B23: =COUNTIF('Sprint Plani'!$A$4:$A$64,$A23) -> 17 | C23: =SUMIF('Sprint Plani'!$A$4:$A$64,$A23,'Sprint Plani'!$H$4:$H$64) -> 36 | D23: =SUMIFS('Sprint Plani'!$H$4:$H$64,'Sprint Plani'!$A$4:$A$64,$A23,'Sprint Plani'!$K$4:$K$64,"Tamamlandı") -> 9 | E23: =IFERROR($D23/$C23,0) -> 0.25 | F23: Gün 7-10 · Yeni veri modeli, görme modeli servisi, kiler ağırlıklı skorlama, chatbot RAG, Flutter iskelet
A24: Hafta 3 | B24: =COUNTIF('Sprint Plani'!$A$4:$A$64,$A24) -> 21 | C24: =SUMIF('Sprint Plani'!$A$4:$A$64,$A24,'Sprint Plani'!$H$4:$H$64) -> 45 | D24: =SUMIFS('Sprint Plani'!$H$4:$H$64,'Sprint Plani'!$A$4:$A$64,$A24,'Sprint Plani'!$K$4:$K$64,"Tamamlandı") -> 0 | E24: =IFERROR($D24/$C24,0) -> 0 | F24: Gün 11-15 · Auth+onboarding, SWIPE destesi, sohbet+fotoğraf, kalori (foto/manuel/barkod), kiler+barkod
A25: Hafta 4 | B25: =COUNTIF('Sprint Plani'!$A$4:$A$64,$A25) -> 23 | C25: =SUMIF('Sprint Plani'!$A$4:$A$64,$A25,'Sprint Plani'!$H$4:$H$64) -> 45 | D25: =SUMIFS('Sprint Plani'!$H$4:$H$64,'Sprint Plani'!$A$4:$A$64,$A25,'Sprint Plani'!$K$4:$K$64,"Tamamlandı") -> 0 | E25: =IFERROR($D25/$C25,0) -> 0 | F25: Gün 16-20 · Tarif detay yeşil/kırmızı/gri, öğrenen profil, 7 gün güven süresi, sadeleştirme, test, teslim
A26: TOPLAM | B26: =SUM(B23:B25) -> 61 | C26: =SUM(C23:C25) -> 126 | D26: =SUM(D23:D25) -> 9 | E26: =IFERROR(D26/C26,0) -> 0.071428571 | F26: Kapasite 126 saat (14 gün × 9 saat)
A28: GUNLUK DAGILIM
A29: Gün | B29: Görev | C29: Saat | F29: Odak
A30: Gün 7 | B30: =COUNTIF('Sprint Plani'!$B$4:$B$64,$A30) -> 4 | C30: =SUMIF('Sprint Plani'!$B$4:$B$64,$A30,'Sprint Plani'!$H$4:$H$64) -> 9 | F30: Backend: yeni kiler modeli, swipe geri bildirim modeli, görme servisi, fotoğraftan malzeme
A31: Gün 8 | B31: =COUNTIF('Sprint Plani'!$B$4:$B$64,$A31) -> 4 | C31: =SUMIF('Sprint Plani'!$B$4:$B$64,$A31,'Sprint Plani'!$H$4:$H$64) -> 9 | F31: Backend: malzeme eşleştirme, kiler ağırlıklı skorlama, swipe destesi, fotoğraftan öğün
A32: Gün 9 | B32: =COUNTIF('Sprint Plani'!$B$4:$B$64,$A32) -> 4 | C32: =SUMIF('Sprint Plani'!$B$4:$B$64,$A32,'Sprint Plani'!$H$4:$H$64) -> 9 | F32: Backend: chatbot RAG, sohbette fotoğraf, öğün kaydı, barkod → kiler
A33: Gün 10 | B33: =COUNTIF('Sprint Plani'!$B$4:$B$64,$A33) -> 5 | C33: =SUMIF('Sprint Plani'!$B$4:$B$64,$A33,'Sprint Plani'!$H$4:$H$64) -> 9 | F33: Flutter: proje kurulumu, tasarım sistemi, 4 sekmeli navigasyon, dio+Riverpod, modeller
A34: Gün 11 | B34: =COUNTIF('Sprint Plani'!$B$4:$B$64,$A34) -> 5 | C34: =SUMIF('Sprint Plani'!$B$4:$B$64,$A34,'Sprint Plani'!$H$4:$H$64) -> 9 | F34: Auth, onboarding anketi, kalori hedefi, yönlendirme kapıları
A35: Gün 12 | B35: =COUNTIF('Sprint Plani'!$B$4:$B$64,$A35) -> 4 | C35: =SUMIF('Sprint Plani'!$B$4:$B$64,$A35,'Sprint Plani'!$H$4:$H$64) -> 9 | F35: SWIPE: kart bileşeni, kaydırma etiketleri, deste yönetimi, 'malzemem yok' akışı
A36: Gün 13 | B36: =COUNTIF('Sprint Plani'!$B$4:$B$64,$A36) -> 4 | C36: =SUMIF('Sprint Plani'!$B$4:$B$64,$A36,'Sprint Plani'!$H$4:$H$64) -> 9 | F36: SOHBET: arayüz, hazır çipler, fotoğraf ekleme, malzeme onay ekranı
A37: Gün 14 | B37: =COUNTIF('Sprint Plani'!$B$4:$B$64,$A37) -> 4 | C37: =SUMIF('Sprint Plani'!$B$4:$B$64,$A37,'Sprint Plani'!$H$4:$H$64) -> 9 | F37: KALORİ: ana ekran, fotoğrafla öğün, arama/barkod, görsel porsiyon
A38: Gün 15 | B38: =COUNTIF('Sprint Plani'!$B$4:$B$64,$A38) -> 4 | C38: =SUMIF('Sprint Plani'!$B$4:$B$64,$A38,'Sprint Plani'!$H$4:$H$64) -> 9 | F38: KİLER: var/bilinmiyor ekranı, barkod tarayıcı, ürün onayı, alışveriş listesi
A39: Gün 16 | B39: =COUNTIF('Sprint Plani'!$B$4:$B$64,$A39) -> 4 | C39: =SUMIF('Sprint Plani'!$B$4:$B$64,$A39,'Sprint Plani'!$H$4:$H$64) -> 9 | F39: Tarif detay (yeşil/kırmızı/gri), porsiyon ölçekleme, 'yaptım' akışı, öğrenen profil
A40: Gün 17 | B40: =COUNTIF('Sprint Plani'!$B$4:$B$64,$A40) -> 5 | C40: =SUMIF('Sprint Plani'!$B$4:$B$64,$A40,'Sprint Plani'!$H$4:$H$64) -> 9 | F40: 7 günlük güven süresi, sadeleştirme, boş/hata durumları, undo, erişilebilirlik
A41: Gün 18 | B41: =COUNTIF('Sprint Plani'!$B$4:$B$64,$A41) -> 4 | C41: =SUMIF('Sprint Plani'!$B$4:$B$64,$A41,'Sprint Plani'!$H$4:$H$64) -> 9 | F41: Testler: birim, görme doğruluğu, uçtan uca senaryolar, performans
... A43: Gün 20 | B43: =COUNTIF('Sprint Plani'!$B$4:$B$64,$A43) -> 5 | C43: =SUMIF('Sprint Plani'!$B$4:$B$64,$A43,'Sprint Plani'!$H$4:$H$64) -> 9 | F43: Diyagramlar, README, demo videosu, sunum, tampon
A45: KAPSAM DEGISIKLIGI OZETI
A46: 1) ALT BAR 4 SEKME: Sohbet · Kesfet (swipe) · Kalori · Kiler. Alisveris listesi sekme degil, Kiler altinda alt ekran.
A47: 2) KILER ARTIK ELLE DOLDURULMUYOR. Yalnizca iki kaynaktan dolar: (a) barkod okutma, (b) sohbete atilan mutfak fotografi. Kullanicidan metin girisi istenmiyor.
...

Sheet Sprint Plani
A1: KALORI SAYACI | KALAN 14 IS GUNU PLANI (Gun 7 - Gun 20)
A2: Kapsam: 4 sekme (Sohbet · Kesfet/Swipe · Kalori · Kiler) || Gorme modeli ile fotograftan malzeme ve ogun cikarma || Kiler yalnizca BARKOD ve FOTOGRAF ile dolar, elle metin girisi yok; kayitlar 7 gun 'var', sonra 'bilinmiyor' || Yigin: Flutter (Dart) + FastAPI + SQLite + MongoDB + cok kipli gorme modeli + Groq/LLaMA + Open Food Facts + Google ML Kit || 14 is gunu x 9 saat = 126 saat kapasite
A3: Hafta | B3: Gün | C3: Görev Kodu | D3: Modül | E3: Atomik Görev Adı | F3: Nasıl Yapılacak / Kullanılacak Teknolojiler | G3: Kabul Kriteri (Definition of Done) | H3: Tahmini Süre (Saat) | I3: Öncelik | J3: Bağımlılık | K3: Durum
A4: Hafta 2 | B4: Gün 7 | C4: W2-T01 | D4: Backend / DB | E4: Kiler Veri Modelinin Yeniden Tasarlanması | F4: pantry_items tablosu 'elle girilen envanter'den 'bildigimiz seyler' listesine cevrilir. Yeni alanlar: availability (var/bilinmiyor), source (barkod/foto/tarif), confirmed_at, confidence_expires_at (confirmed_at + 7 gun), detected_confidence (gorme modelinin guven skoru). Kaldirilan/pasiflestirilen: min_threshold_base (esik mantigi kapsam disi). Alembic ile migration uretilir (render_as_batch=True). | G4: alembic upgrade head hatasiz; yeni alanlar tabloda; eski kayitlar availability='bilinmiyor' olarak gecirilmis. | H4: 2.5 | I4: Kritik | J4: - | K4: Tamamlandı
A5: Hafta 2 | B5: Gün 7 | C5: W2-T02 | D5: Backend / DB | E5: Swipe Geri Bildirim Modeli | F5: recipe_feedback tablosu genisletilir: action enum (gordu / begenmedim / yapacagim / kaydetti / yaptim), reason enum (sevmedim / cok_uzun / malzeme_yok / null), missing_ingredient_id (FK -> ingredients), session_id (FK -> swipe_sessions). Yeni tablo: swipe_sessions (id, user_id, started_at, ended_at, filters_json). Indeks: (user_id, recipe_id), (session_id). | G5: Migration uygulanmis; ayni tarife farkli oturumlarda farkli geri bildirim yazilabiliyor. | H5: 1.5 | I5: Kritik | J5: W2-T01 | K5: Tamamlandı
A6: Hafta 2 | B6: Gün 7 | C6: W2-T03 | D6: Backend / AI | E6: Görme Modeli Servis Katmanı (Soyutlama) | F6: services/vision_service.py: cok kipli (multimodal) gorme modeline baglanan soyut arayuz. VisionProvider arayuzu + GroqVisionProvider / OpenAIVisionProvider uygulamalari; saglayici .env'den secilir. Goruntu base64'e cevrilir, timeout 20 sn, 429/500 icin exponential backoff, token/maliyet logu. Ayrica FakeVisionProvider (sabit yanit) yazilir - internetsiz gelistirme ve test icin. | G6: Ornek bir fotografa 5 sn altinda JSON yanit donuyor; saglayici .env ile degistirilebiliyor; sahte saglayici testte calisiyor. | H6: 3 | I6: Kritik | J6: - | K6: Tamamlandı
A7: Hafta 2 | B7: Gün 7 | C7: W2-T04 | D7: Backend / AI | E7: Fotoğraftan Malzeme Çıkarma Ucu | F7: POST /api/v1/vision/ingredients (multipart foto). Sistem promptu: 'Bu fotograftaki YENILEBILIR malzemeleri listele, JSON dizi dondur, emin olmadiklarini dusuk confidence ile isaretle.' Donen ham adlar ingredients + ingredient_aliases tablolariyla eslestirilir (W1-T12'deki normalize_text ile). Eslesmeyenler unmatched_ingredients'a yazilir. Yanit: [{raw_name, canonical_name|null, display_name, confidence}]. | G7: Bir buzdolabi fotografi gonderildiginde en az 5 malzeme donuyor; eslesenler canonical_name tasiyor, eslesmeyenler null. | H7: 2 | I7: Kritik | J7: W2-T03 | K7: Tamamlandı
A8: Hafta 2 | B8: Gün 8 | C8: W2-T05 | D8: Backend / Algoritma | E8: Malzeme Eşleştirme ve Bulanık Arama | F8: Uc asamali eslestirme: (1) ingredients.canonical_name tam eslesme, (2) ingredient_aliases.alias tam eslesme, (3) rapidfuzz token_set_ratio ile %85 uzeri bulanik eslesme. Saf fonksiyon, pytest ile 20+ vaka. Hem gorme modeli ciktisi hem chatbot metni bu fonksiyondan gecer. | G8: Test setinde eslestirme dogrulugu %90 uzeri; 'domates', 'Domates', 'salkim domates' ayni kanonik ada dusuyor. | H8: 2 | I8: Kritik | J8: W2-T04 | K8: Yapılacak
A9: Hafta 2 | B9: Gün 8 | C9: W2-T06 | D9: Backend / Algoritma | E9: Kiler Ağırlıklı Tarif Skorlama | F9: MongoDB aggregation: $setIntersection ile kiler-tarif kesisimi. AGIRLIK FARKI: availability='var' malzemeler 1.0, 'bilinmiyor' malzemeler 0.4 puan alir. final_score = 0.50*kiler_skoru + 0.20*kalori_uygunlugu + 0.20*zevk_vektoru + 0.10*sure_uygunlugu. Diyet ($in) ve alerjen ($nin) filtreleri zorunlu. Skor kirilimi yanitta doner (aciklanabilirlik). | G9: Kilerinde taze domates olan kullaniciya domatesli tarifler belirgin sekilde ust siralarda doniyor; alerjenli tarif hicbir kosulda donmuyor. | H9: 3 | I9: Kritik | J9: W2-T05 | K9: Yapılacak
A10: Hafta 2 | B10: Gün 8 | C10: W2-T07 | D10: Backend / Algoritma | E10: Swipe Destesi Ucu ve Oturum Filtreleme | F10: GET /api/v1/recipes/deck?session_id=&limit=10. Filtreleme kurallari: (a) bu oturumda gorulen tarifler tekrar gelmez, (b) 'sevmedim' denenler KALICI olarak elenir, (c) 'cok_uzun' denince o oturumda sure esigi 30 dk'ya duser, (d) 'malzeme_yok' denenler 7 gun elenir. POST /api/v1/recipes/{id}/swipe ile geri bildirim yazilir. | G10: 10 kartlik deste doniyor; ayni oturumda ikinci istekte tekrar eden tarif yok; 'sevmedim' denen tarif bir daha hic donmuyor. | H10: 2.5 | I10: Kritik | J10: W2-T06 | K10: Yapılacak
A11: Hafta 2 | B11: Gün 8 | C11: W2-T08 | D11: Backend / AI | E11: Fotoğraftan Öğün ve Kalori Tahmini Ucu | F11: POST /api/v1/vision/meal (multipart foto). Prompt: 'Tabaktaki yemegi tani. Yanindaki catal/bicak varsa OLCEK REFERANSI olarak kullanip porsiyon buyuklugunu tahmin et.' Yanit: {yemek_adi, tahmini_porsiyon (kucuk/orta/buyuk), tahmini_gram, guven}. Tahmin ingredients/products tablosuyla eslestirilip kalori hesaplanir. ONEMLI: yanit 'tahmin' olarak isaretlenir, kullanici onayi zorunludur. | G11: Bir yemek fotografi gonderildiginde yemek adi + porsiyon + kalori tahmini doniyor; guven skoru yanitta yer aliyor. | H11: 1.5 | I11: Kritik | J11: W2-T03 | K11: Yapılacak
A12: Hafta 2 | B12: Gün 9 | C12: W2-T09 | D12: Backend / AI | E12: Chatbot RAG Mimarisi | F12: POST /api/v1/chat. Akis: (1) kullanici mesajindan niyet ve kisitlar cikarilir (hafif / mercimekli / 30 dk alti gibi), (2) SQLite'tan kiler + profil + diyet/alerjen + kalan kalori cekilir, (3) W2-T06/T07 filtreleriyle en iyi 5-8 tarif alinir, (4) kompakt JSON olarak prompt baglamina gomulur, (5) LLM yanit + onerilen_tarif_idleri dondurur. Cikti sozlesmesi: {mesaj, onerilen_tarif_idleri[], uygulanan_filtreler[]}. | G12: 'Hafif, mercimekli, 30 dakikada yapabilecegim bir sey' istegine bagalamdaki tariflerden gecerli JSON doniyor; uydurma tarif yok. | H12: 3.5 | I12: Kritik | J12: W2-T06 | K12: Yapılacak
A13: Hafta 2 | B13: Gün 9 | C13: W2-T10 | D13: Backend / AI | E13: Chatbot Fotoğraf Desteği ve Kiler Yazımı | F13: Sohbet mesajina foto eklenebilir: POST /api/v1/chat (multipart). Foto once W2-T04'ten gecer, cikan malzemeler ONAY BEKLER (dogrudan kilere yazilmaz). Onay ucunda: POST /api/v1/pantry/confirm-detected -> secilen malzemeler pantry_items'a availability='var', source='foto', confidence_expires_at=simdi+7gun ile yazilir. chat_messages tablosuna image_url ve detected_ingredients alanlari eklenir. | G13: Fotograf gonderilince malzeme listesi doniyor; onaylanan malzemeler kilere 7 gunluk 'var' olarak yaziliyor. | H13: 1.5 | I13: Kritik | J13: W2-T09 | K13: Yapılacak
A14: Hafta 2 | B14: Gün 9 | C14: W2-T11 | D14: Backend / Kalori | E14: Öğün Kaydı API'leri | F14: POST /api/v1/meals (ogun tipi, kaynak: manuel/foto/barkod, urun/tarif referansi, porsiyon), GET /api/v1/meals/daily?date= (gunluk toplam kcal + makro kirilimi), DELETE /api/v1/meals/{id}. ANLIK GORUNTU ILKESI: item_name, calories ve makrolar kayit aninda kopyalanir. logged_date istemciden gelir (kullanicinin yerel gunu). | G14: Ayni gune 3 ogun eklendiginde gunluk ozet dogru toplami ve makro kirilimini donuyor. | H14: 2 | I14: Kritik | J14: - | K14: Yapılacak
A15: Hafta 2 | B15: Gün 9 | C15: W2-T12 | D15: Backend / Barkod | E15: Barkod → Ürün → Kiler Ucu | F15: POST /api/v1/pantry/scan {barcode}. Once products onbellegine, yoksa Open Food Facts API'sine (httpx, 5 sn timeout, 2 retry) bakilir. Urun ingredients sozlugu ile eslestirilir. Sonuc onay ekranina doner; onaylaninca pantry_items'a availability='var', source='barkod' ile yazilir. Bulunamayan barkod icin manuel urun kaydi (source='user') fallback'i. | G15: Gercek bir market urunu barkodu ile urun adi + kalori doniyor ve kilere 'var' olarak yaziliyor. | H15: 2 | I15: Yüksek | J15: W2-T01 | K15: Yapılacak
... A64: Hafta 4 | B64: Gün 20 | C64: W4-T23 | D64: Tampon | E64: Tampon Süre / Kritik Hata Payı | F64: Beklenmedik native build hatalari, API kotasi, cihaz uyumsuzlugu icin ayrilan pay. Kullanilmazsa V2 backlog'undan bir madde cekilir (oncelik: gida israfi raporu). | G64: Plan sapmasi yasanmadan teslim tamamlandi. | H64: 1 | I64: Orta | J64: - | K64: Yapılacak
A65: TOPLAM | H65: =SUM(H4:H64) -> 126 | I65: =COUNTA(C4:C64)&" görev" -> 61 görev
A67: KAPASITE: 14 is gunu x 9 saat = 126 saat. Plan toplami 126 saat - tam oturuyor, tampon W4-T23 (1 saat) icinde.
A68: BASLANGIC VARSAYIMI: Backend ve veri katmani BITMIS kabul edilir (eski plandaki W1-T01 ... W1-T12): 22 tablo, JWT auth, Alembic, 100+ tarif (MongoDB), 170 malzeme + 533 alias (SQLite), birim donusum servisi, 43 birim testi. Flutter tarafi SIFIRDAN baslar.
A69: KAPSAM DEGISIKLIGI: (1) Alt bar 4 sekme: Sohbet, Kesfet (swipe), Kalori, Kiler - alisveris listesi Kiler altinda alt ekran. (2) Kiler ELLE DOLDURULMAZ; yalnizca barkod okutma ve fotograf tanima ile dolar. (3) Her kiler kaydi 7 gun 'var', sonra otomatik 'bilinmiyor'; oneri motoru ikisini farkli agirlikla puanlar. (4) Fis OCR ve gorsel obje tanima icin ozel model egitimi KAPSAM DISI - yerine cok kipli gorme modeli API'si kullanilir.
A70: ELLE DOLDURULACAK TEK ALAN: K sutunu (Durum). Acilir listeden secim yapin.

Sheet Ekran Haritasi
A1: EKRAN HARITASI | Yapilacak Tum Arayuzler
A2: Alt bar 4 sekme; digerleri alt ekran veya tam ekran rota. UI maket prompt'lari bu listeye gore uretildi.
A3: # | B3: Ekran | C3: Konum | D3: İçerik | E3: Temel Etkileşim | F3: Görev
A4: 1 | B4: Açılış (Splash) | C4: Tam ekran | D4: Logo, uygulama adı, oturum kontrolü | E4: Otomatik yönlendirme | F4: W3-T05
A5: 2 | B5: Giriş | C5: Tam ekran | D5: E-posta + şifre, şifre göster/gizle | E5: Giriş Yap → ana ekran | F5: W3-T02
A6: 3 | B6: Kayıt | C6: Tam ekran | D6: Ad, e-posta, şifre + güç göstergesi, KVKK onayı | E6: Kayıt Ol → onboarding | F6: W3-T02
A7: 4 | B7: Onboarding 1/4 | C7: Tam ekran | D7: Doğum yılı, cinsiyet, boy, kilo, aktivite | E7: Devam / Atla | F7: W3-T03
A8: 5 | B8: Onboarding 2/4 | C8: Tam ekran | D8: Hedef kartları (ver/koru/al) + hane büyüklüğü | E8: Devam / Atla | F8: W3-T03
A9: 6 | B9: Onboarding 3/4 | C9: Tam ekran | D9: Diyet çipleri + alerjen çipleri (kırmızı stil) | E9: Devam / Atla | F9: W3-T03
A10: 7 | B10: Onboarding 4/4 | C10: Tam ekran | D10: 'Sevdiğin 5 yemeği seç' görsel grid | E10: Bitir → hedef kalori gösterimi | F10: W3-T03
A11: 8 | B11: KEŞFET (Swipe) | C11: Sekme 2 — ana ekran | D11: Tarif kart destesi, uyum rozeti, kalori/süre | E11: Sol/Sağ/Yukarı kaydırma | F11: W3-T06
A12: 9 | B12: Swipe — neden çipleri | C12: Sekme 2 üstü | D12: Sola kaydırma sonrası 3 sn beliren çip satırı | E12: Sevmedim / Çok uzun / Malzemem yok | F12: W3-T07
A13: 10 | B13: Swipe — 'Malzemem yok' | C13: Alt sayfa | D13: Tarifin eksik malzeme listesi, çoklu seçim | E13: Seçilenler alışveriş listesine | F13: W3-T09
A14: 11 | B14: Swipe — deste bitti | C14: Sekme 2 | D14: Boş durum görseli + iki eylem butonu | E14: Fotoğraf çek / Barkod okut | F14: W3-T08
A15: 12 | B15: SOHBET | C15: Sekme 1 | D15: Mesaj baloncukları, mini tarif kartları | E15: Yaz / çip seç / fotoğraf ekle | F15: W3-T10
... A31: 28 | B31: Profil | C31: Tam ekran | D31: Hedefler, tercihler, KVKK (veri indir / hesap sil) | E31: Ayar değiştir | F31: W4-T14

Sheet DB ve Backend Degisiklikleri
A1: KAPSAM REVIZYONUNUN VERITABANI VE BACKEND ETKISI
A2: Mevcut 22 tablolu semanin uzerine yapilacak degisiklikler. Her satir bir Alembic migration veya yeni uc anlamina gelir.
A3: Tür | B3: Tablo / Modül | C3: Alan / Uç | D3: İşlem | E3: Açıklama ve Gerekçe | F3: Görev | G3: Öncelik
A4: Şema | B4: pantry_items | C4: availability | D4: EKLE | E4: TEXT CHECK ('var','bilinmiyor','bitti'). Kilerin yeni anlami: envanter degil, 'bildigimiz seyler'. Oneri skorlamasinda 'var'=1.0, 'bilinmiyor'=0.4 agirlik. | F4: W2-T01 | G4: Kritik
A5: Şema | B5: pantry_items | C5: source | D5: EKLE | E5: TEXT CHECK ('barkod','foto','tarif','sistem'). Kaydin nereden geldigi. Elle giris ARTIK YOK, bu yuzden 'manuel' degeri yok. | F5: W2-T01 | G5: Kritik
A6: Şema | B6: pantry_items | C6: confirmed_at | D6: EKLE | E6: DATETIME. Kullanicinin son 'bu bende var' onayi. Barkod/foto ile eklendiginde otomatik doldurulur. | F6: W2-T01 | G6: Kritik
A7: Şema | B7: pantry_items | C7: confidence_expires_at | D7: EKLE | E7: DATETIME = confirmed_at + 7 gun. Bu tarihten sonra availability otomatik 'bilinmiyor' olur. | F7: W2-T01 | G7: Kritik
A8: Şema | B8: pantry_items | C8: detected_confidence | D8: EKLE | E8: REAL 0-1. Gorme modelinin bu malzemeye verdigi guven skoru. Dusuk olanlar onay ekraninda varsayilan olarak ISARETSIZ gelir. | F8: W2-T01 | G8: Yüksek
A9: Şema | B9: pantry_items | C9: min_threshold_base | D9: KALDIR | E9: Kritik esik mantigi kapsam disi birakildi (alisveris listesi otomasyonu kesildi). Sutun migration'da dusurulur. | F9: W2-T01 | G9: Orta
A10: Şema | B10: pantry_items | C10: expiry_date, opened_at | D10: KALDIR | E10: SKT takibi kapsam disi. Kullanicidan tarih girmesini istemek 'en basit uygulama' hedefiyle celisiyor. | F10: W2-T01 | G10: Orta
A11: Şema | B11: pantry_items | C11: (user_id, ingredient_id) | D11: DEGISTIR | E11: UNIQUE kisiti korunur ama upsert mantigi degisir: ayni malzeme tekrar tespit edilirse yeni satir acilmaz, confirmed_at yenilenir. | F11: W2-T01 | G11: Kritik
A12: Şema | B12: recipe_feedback | C12: action | D12: DEGISTIR | E12: Enum genisletildi: gordu / begenmedim / yapacagim / kaydetti / yaptim. 'gordu' swipe destesinde gosterilen ama aksiyon alinmayan kartlar icin. | F12: W2-T02 | G12: Kritik
A13: Şema | B13: recipe_feedback | C13: reason | D13: EKLE | E13: TEXT CHECK ('sevmedim','cok_uzun','malzeme_yok') veya NULL. Swipe sonrasi cip secimi. NULL = kullanici sebep belirtmedi (zorunlu degil). | F13: W2-T02 | G13: Kritik
A14: Şema | B14: recipe_feedback | C14: missing_ingredient_id | D14: EKLE | E14: INTEGER FK -> ingredients. reason='malzeme_yok' oldugunda hangi malzemenin eksik oldugu. Alisveris listesini besler. | F14: W2-T02 | G14: Kritik
... A32: Config | B32: settings | C32: PANTRY_CONFIDENCE_DAYS | D32: EKLE | E32: Varsayilan 7. Guven suresi sabit kodlanmaz, ayardan okunur (sunumda 'deneyip ayarlanabilir' demek icin). | F32: W2-T01 | G32: Orta

Sheet Maliyet Analizi
A1: MALIYET ANALIZI | Gorme Modeli Dahil
A2: Yeni kalem: cok kipli gorme modeli. Fotograf basina maliyet dusuk ama kullanim sikligina bagli olarak buyuyebilir.
A3: Maliyet Kalemi | B3: Açıklama | C3: Optimize Edilmemiş Aylık ($) | D3: Ucuza Çözüm / Alternatif | E3: Optimize Aylık ($) | F3: Yıllık Tasarruf ($) | G3: Staj MVP'sinde Gerekli mi?
A4: Görme modeli (fotoğraf) | B4: Mutfak ve tabak fotoğraflarının analizi | C4: 40 | D4: Görüntüyü 1600px'e küçült ve %80 kaliteye sıkıştır (token maliyeti düşer); aynı fotoğrafın hash'ini önbellekle; kullanıcı başına günlük limit | E4: 6 | F4: =(C4-E4)*12 -> 408 | G4: Evet
A5: LLM / Chatbot API | B5: Sohbet asistanının token maliyeti | C5: 35 | D5: Groq üzerinde LLaMA 3 + llm_cache yanıt önbelleği + günlük limit | E5: 2 | F5: =(C5-E5)*12 -> 396 | G5: Evet
A6: Sunucu / Backend | B6: FastAPI barındırma | C6: 12 | D6: Render / Railway ücretsiz katmanı | E6: 0 | F6: =(C6-E6)*12 -> 144 | G6: Evet
A7: Yönetilen Veritabanı | B7: PostgreSQL / MongoDB barındırma | C7: 15 | D7: MongoDB Atlas M0 (ücretsiz) + SQLite dosyası | E7: 0 | F7: =(C7-E7)*12 -> 180 | G7: Evet
A8: Barkod Tanıma | B8: Bulut görüntü işleme | C8: 10 | D8: mobile_scanner (Google ML Kit) cihaz üzerinde — ücretsiz, offline | E8: 0 | F8: =(C8-E8)*12 -> 120 | G8: Evet
A9: Gıda / Barkod Veritabanı | B9: FatSecret / Nutritionix ücretli plan | C9: 20 | D9: Open Food Facts (ODbL, ücretsiz) | E9: 0 | F9: =(C9-E9)*12 -> 240 | G9: Evet
A10: Fotoğraf depolama | B10: Yüklenen görsellerin saklanması | C10: 8 | D10: SAKLAMA YOK: fotoğraf işlendikten sonra silinir. Yalnızca sonuç ve hash tutulur (KVKK + maliyet) | E10: 0 | F10: =(C10-E10)*12 -> 96 | G10: Evet
A11: Görsel CDN | B11: Tarif görselleri | C11: 5 | D11: Unsplash/Pexels bağlantısı + cihazda cached_network_image | E11: 0 | F11: =(C11-E11)*12 -> 60 | G11: Evet
A12: Hata İzleme | B12: Sentry / APM | C12: 26 | D12: Sentry ücretsiz katmanı | E12: 0 | F12: =(C12-E12)*12 -> 312 | G12: Kısmen
A13: Push Bildirim | B13: Bildirim altyapısı | C13: 5 | D13: flutter_local_notifications (cihazda, sunucu gerekmez) | E13: 0 | F13: =(C13-E13)*12 -> 60 | G13: Hayır
A14: Alan Adı + SSL | B14: Backend adresi | C14: 1.5 | D14: Cloudflare ücretsiz SSL | E14: 1.5 | F14: =(C14-E14)*12 -> 0 | G14: Hayır
A15: Google Play Hesabı | B15: Tek seferlik 25 $ | C15: 2.08 | D15: Staj teslimi için gerekmez | E15: 2.08 | F15: =(C15-E15)*12 -> 0 | G15: Hayır (V2)
A16: Apple Developer | B16: Yıllık 99 $ | C16: 8.25 | D16: iOS kapsam dışı — Windows'ta derlenemiyor | E16: 8.25 | F16: =(C16-E16)*12 -> 0 | G16: Hayır (V2)
A17: TOPLAM | C17: =SUM(C4:C16) -> 187.83 | D17: Optimize kurulumda aylık gider ~8 $ | E17: =SUM(E4:E16) -> 19.83 | F17: =SUM(F4:F16) -> 2016
A19: GORME MODELI MALIYETI: Fotograf basina yaklasik 0.001-0.004 $. Gunde 50 fotograf = ayda ~3-6 $. Sikistirma ve onbellekleme ile alt sinira yakin kalinir.
A20: MALIYET DUSURME: (1) Goruntuyu 1600px/%80 kaliteye sikistir - token maliyeti belirgin duser. (2) Ayni fotografin hash'ini onbellekle. (3) Kullanici basina gunluk fotograf limiti. (4) Barkod ve OCR cihaz uzerinde calisir, buluta gitmez. (5) Fotograflar SAKLANMAZ - islenip silinir.
A21: STAJ SURESINCE gercek maliyet: yalnizca sen ve birkac test kullanicisi kullanacagi icin pratikte 0-3 $ arasinda kalir.

Sheet Risk Yonetimi
A1: RISK YONETIMI | Kalan 14 Gun
A2: Kapsam revizyonu bazi riskleri kaldirdi, bazilarini ekledi. Olasilik/Etki: Dusuk / Orta / Yuksek.
A3: Risk | B3: Olasılık | C3: Etki | D3: Erken Uyarı Sinyali | E3: Önlem / B Planı
A4: Görme modeli doğruluğunun düşük olması | B4: Yüksek | C4: Yüksek | D4: Test setinde recall %60'ın altına düşerse. | E4: Onay ekranı ZORUNLU: kullanıcı yanlışı siler, eksiği ekler. Düşük güvenli malzemeler varsayılan işaretsiz gelir. Prompt iyileştirmesi (W4-T11). Son çare: fotoğraf akışı 'yardımcı' olarak konumlanır, tek yol olmaz — barkod ve arama hep açık kalır.
A5: Fotoğraftan porsiyon tahmininin yanıltıcı olması | B5: Yüksek | C5: Orta | D5: Tahminler sürekli 2 katı veya yarısı çıkıyorsa. | E5: Sonuç 'tahmin' olarak açıkça etiketlenir ve DÜZENLENEBİLİR sunulur. Çatal/bıçak ölçek referansı istenir. Sunumda 'ölçüm değil, başlangıç noktası' diye anlatılır — abartılı iddia güven kaybettirir.
A6: Flutter tarafının 10 günde yetişmemesi | B6: Yüksek | C6: Yüksek | D6: Gün 13 sonunda sohbet ve swipe ekranları bitmemişse. | E6: Öncelik sırası: Swipe > Kalori > Sohbet > Kiler. Sıkışırsa sohbet arayüzü sadeleştirilir (mini kart yerine düz liste), görsel porsiyon seçimi (W3-T17) ve erişilebilirlik geçişi (W4-T09) feda edilir. Toplam 2.5 saat esnetme payı.
A7: Fiziksel Android test cihazı olmaması | B7: Yüksek | C7: Yüksek | D7: Kamera akışları emülatörde doğrulanamıyorsa. | E7: BarcodeScanner soyutlaması + FakeVisionProvider ile geliştirme cihazsız sürer. Emülatör Camera->Webcam0 ayarı gerçek barkod okutabiliyor. W4-T18'de bir günlüğüne ödünç cihaz alınır (öncelikle staj yerinden istenir).
A8: LLM veya görme API'sinin kotası/gecikmesi | B8: Orta | C8: Yüksek | D8: Yanıt süresi 8 saniyeyi geçiyor veya 429 dönüyorsa. | E8: Her iki servis de sağlayıcı arayüzü arkasında soyutlandı — tek satırla başka sağlayıcıya geçilir. API çökerse uygulama ÇÖKMEZ: kural tabanlı öneriye düşer. llm_cache tekrarlayan soruları API'ye hiç göndermez.
A9: 7 günlük güven süresinin kullanıcıyı yanıltması | B9: Orta | C9: Orta | D9: Kullanıcı 'bende yok' dediği tarifleri sürekli görüyorsa. | E9: Süre sabit kodlanmaz, PANTRY_CONFIDENCE_DAYS ayarından okunur. 'Emin değiliz' bölümündeki [Var]/[Bitti] hızlı butonları kullanıcının tek dokunuşla düzeltmesini sağlar. Sunumda 'deneyle ayarlanabilir parametre' diye anlatılır.
A10: Swipe jestinin yanlış sinyal üretmesi | B10: Orta | C10: Orta | D10: Kullanıcılar yanlışlıkla sola kaydırıp sonra şikayet ediyorsa. | E10: Dört köşegen yerine üç yön (sol/sağ/yukarı) seçildi. Sürüklerken kartın üstünde büyük renkli etiket görünür — kullanıcı bırakmadan önce ne olacağını görür. Sola kaydırmada neden çipi ZORUNLU DEĞİL, dokunulmazsa genel 'hayır' kaydedilir.
A11: Fotoğraf yükleme süresinin uzun olması | B11: Orta | C11: Orta | D11: 3G/zayıf bağlantıda yükleme 10 saniyeyi geçiyorsa. | E11: İstemci tarafında sıkıştırma (1600px, %80) — 3 MB'lik foto 500 KB altına iner. Yükleme sırasında ilerleme göstergesi ve iptal seçeneği.
A12: KVKK: fotoğraf ve sağlık verisi | B12: Orta | C12: Yüksek | D12: Sunum veya yayın öncesi veri politikası sorulduğunda. | E12: Fotoğraflar SAKLANMAZ — işlenip silinir, yalnızca sonuç ve hash tutulur. Onboarding'de aydınlatma metni ve rıza. W4-T14'te veri dışa aktarma ve kalıcı hesap silme uçları.
A13: Kapsam kayması (scope creep) | B13: Yüksek | C13: Yüksek | D13: Plan dışı bir özellik için 'sadece yarım gün sürer' denildiğinde. | E13: Bu revizyon zaten bir kapsam DARALTMASIDIR. Kesilen her şey (fiş OCR, israf raporu, eşik otomasyonu, SKT, iOS) yazılı olarak V2/V3'e alındı. Yeni fikir doğrudan backlog'a yazılır, sprinte alınmaz.
A14: Zaman tahminlerinin sapması | B14: Orta | C14: Orta | D14: Herhangi bir günün sonunda tamamlanan saat 7'nin altındaysa. | E14: Günlük 9 saat iddialı bir tempo. Esnetme payı: W3-T17 (1 saat), W4-T08 (1.5 saat), W4-T09 (1.5 saat), W4-T23 tampon (1 saat) = 5 saat. Bunlar kesilirse algoritma ve ana akışlar korunur.
A15: Emülatör sistem servisi çökmesi | B15: Orta | C15: Orta | D15: 'Can't find service: package', 'Activity class does not exist' hataları. | E15: Emülatörü soğuk başlat: adb emu kill; adb kill-server; emulator -avd Pixel_7 -no-snapshot-load. Tekrarlarsa Wipe Data. mobile/README.md'de sorun giderme bölümü var.

Sheet V2-V3 Backlog
A1: KAPSAM DISI | V2 ve V3 YOL HARITASI
A2: Bu revizyonla kesilen ve zaten ertelenmis olan maddeler, gerekceleriyle.
A3: Sürüm | B3: Öncelik | C3: Modül | D3: Özellik | E3: Neden Kapsam Dışı? | F3: Nasıl Yapılacak | G3: Süre
A4: V2 | B4: Çok Yüksek | C4: Raporlama | D4: Gıda İsrafı ve Tasarruf Raporu | E4: Bu revizyonda kiler hareket günlüğü (pantry_events) kesildiği için veri kaynağı yok. Önce çekirdek döngünün tuttuğu doğrulanmalı. | F4: pantry_events tablosu geri eklenir; 'bitti' işaretlenen ve süresi dolan malzemelerden israf tahmini üretilir. 'Bu ay ~340 TL tasarruf ettin' kartı. | G4: 1-2 hafta
A5: V2 | B5: Çok Yüksek | C5: Kiler | D5: Tüketim Hızı ve Öngörülü Liste | E5: Anlamlı sonuç için en az 3 haftalık kullanım verisi gerekiyor. | F5: Barkod ve fotoğraf kayıtlarının sıklığından malzeme bazlı tüketim hızı çıkarılır; ürün bitmeden alışveriş listesine eklenir. | G5: 1 hafta
A6: V2 | B6: Yüksek | C6: Kiler | D6: Kritik Eşik ve SKT Takibi | E6: Kullanıcıdan miktar ve tarih girmesini gerektiriyor — 'en basit uygulama' hedefiyle çelişiyor. | F6: İsteğe bağlı 'gelişmiş mod' olarak geri getirilir; varsayılan kapalı kalır. | G6: 4-5 gün
A7: V2 | B7: Yüksek | C7: AI | D7: Haftalık Beslenme Özeti | E7: LLM altyapısı kurulu ama özet katmanı kapsamı şişirirdi. | F7: meal_logs + swipe geçmişi haftalık özetlenip LLM'e verilir: 'Bu hafta protein hedefinin %70'indesin, akşamları geç yiyorsun'. | G7: 1 hafta
A8: V2 | B8: Yüksek | C8: Kullanıcı | D8: Hane Paylaşımı (Ortak Kiler) | E8: Kiler gerçekte evsel bir kaynak; tek kullanıcılık model planı basitleştiriyor. | F8: households + household_members tabloları; pantry_items'a household_id. Tek migration, geriye dönük doldurma. | G8: 4-5 gün
A9: V2 | B9: Orta | C9: Kalori | D9: Su Takibi ve Adım Entegrasyonu | E9: Kalori dengesinin ikinci yarısı; MVP'de alım tarafına odaklanıldı. | F9: Health Connect (Android) ile adım/yakılan kalori; su için basit sayaç. | G9: 1 hafta
A10: V2 | B10: Orta | C10: Altyapı | D10: Çevrimdışı Mod | E10: İnternet varsayımıyla ilerlemek geliştirme hızını iki katına çıkarıyor. | F10: drift/sqflite yerel kopya + değişiklik kuyruğu + çakışma çözümlemeli senkronizasyon. | G10: 2 hafta
A11: V2 | B11: Orta | C11: Platform | D11: iOS Sürümü ve Mağaza Yayını | E11: Geliştirme ortamı Windows; iOS derlemesi macOS + Xcode gerektiriyor. | F11: Mac erişimi veya Codemagic bulut derlemesi; ardından mağaza süreçleri. | G11: 1-2 hafta
A12: V3 | B12: Yüksek | C12: OCR | D12: Fişten Ürün Okuma | E12: Veri temizleme + NLP süreci; tek başına 10 iş günü yutar. | F12: ML Kit Text Recognition + RegEx/LLM ayrıştırma. ingredient_aliases ve unmatched_ingredients altyapısı hazır bekliyor. | G12: 3-4 hafta
A13: V3 | B13: Düşük | C13: Görüntü İşleme | D13: Özel Obje Tanıma Modeli | E13: Çok kipli LLM API'si bu ihtiyacı zaten karşılıyor — model eğitmenin getirisi yok. | F13: Yalnızca maliyet veya çevrimdışı çalışma kritik hale gelirse: YOLOv8 + TensorFlow Lite. | G13: 4-8 hafta
A14: V3 | B14: Düşük | C14: Sosyal | D14: Tarif Paylaşımı | E14: Veri yükü ve moderasyon maliyeti; belirli bir kullanıcı kütlesinden sonra anlamlı. | F14: Kullanıcı tarifleri, beğeni/yorum, moderasyon kuyruğu. | G14: 3-4 hafta
